2025-08-25 13:53:11 INFO root Start primary API version 1.8.21
2025-08-25 13:53:12 INFO root loading script: main
2025-08-25 13:53:13 INFO root successfully loaded script: main
2025-08-25 13:53:14 ERROR root Failed to run callback function: Timert
Traceback (most recent call last):
  File "/main.py", line 13, in t
    print(error)
NameError: name 'error' is not defined
2025-08-25 13:53:15 ERROR root Failed to run callback function: Timert
Traceback (most recent call last):
  File "/main.py", line 13, in t
    print(error)
NameError: name 'error' is not defined
2025-08-25 13:53:16 ERROR root Failed to run callback function: Timert
Traceback (most recent call last):
  File "/main.py", line 13, in t
    print(error)
NameError: name 'error' is not defined
2025-08-25 13:53:17 ERROR root Failed to run callback function: Timert
Traceback (most recent call last):
  File "/main.py", line 13, in t
    print(error)
NameError: name 'error' is not defined
2025-08-25 13:53:18 ERROR root Failed to run callback function: Timert
Traceback (most recent call last):
  File "/main.py", line 13, in t
    print(error)
NameError: name 'error' is not defined
2025-08-25 13:53:19 ERROR root Failed to run callback function: Timert
Traceback (most recent call last):
  File "/main.py", line 13, in t
    print(error)
NameError: name 'error' is not defined
2025-08-25 13:53:20 ERROR root Failed to run callback function: Timert
Traceback (most recent call last):
  File "/main.py", line 13, in t
    print(error)
NameError: name 'error' is not defined
2025-08-25 13:53:21 ERROR root Failed to run callback function: Timert
Traceback (most recent call last):
  File "/main.py", line 13, in t
    print(error)
NameError: name 'error' is not defined
2025-08-25 13:53:22 ERROR root Failed to run callback function: Timert
Traceback (most recent call last):
  File "/main.py", line 13, in t
    print(error)
NameError: name 'error' is not defined
2025-08-25 13:53:23 ERROR root Failed to run callback function: Timert
Traceback (most recent call last):
  File "/main.py", line 13, in t
    print(error)
NameError: name 'error' is not defined
2025-08-25 13:53:24 ERROR root Failed to run callback function: Timert
Traceback (most recent call last):
  File "/main.py", line 13, in t
    print(error)
NameError: name 'error' is not defined
2025-08-25 13:53:25 ERROR root Failed to run callback function: Timert
Traceback (most recent call last):
  File "/main.py", line 13, in t
    print(error)
NameError: name 'error' is not defined
2025-08-25 13:53:26 ERROR root Failed to run callback function: Timert
Traceback (most recent call last):
  File "/main.py", line 13, in t
    print(error)
NameError: name 'error' is not defined
2025-08-25 13:53:27 ERROR root Failed to run callback function: Timert
Traceback (most recent call last):
  File "/main.py", line 13, in t
    print(error)
NameError: name 'error' is not defined
2025-08-25 13:53:28 ERROR root Failed to run callback function: Timert
Traceback (most recent call last):
  File "/main.py", line 13, in t
    print(error)
NameError: name 'error' is not defined
2025-08-25 13:53:29 ERROR root Failed to run callback function: Timert
Traceback (most recent call last):
  File "/main.py", line 13, in t
    print(error)
NameError: name 'error' is not defined
2025-08-25 13:53:30 ERROR root Failed to run callback function: Timert
Traceback (most recent call last):
  File "/main.py", line 13, in t
    print(error)
NameError: name 'error' is not defined
2025-08-25 13:53:31 ERROR root Failed to run callback function: Timert
Traceback (most recent call last):
  File "/main.py", line 13, in t
    print(error)
NameError: name 'error' is not defined
2025-08-25 13:53:32 ERROR root Failed to run callback function: Timert
Traceback (most recent call last):
  File "/main.py", line 13, in t
    print(error)
NameError: name 'error' is not defined
2025-08-25 13:53:33 ERROR root Failed to run callback function: Timert
Traceback (most recent call last):
  File "/main.py", line 13, in t
    print(error)
NameError: name 'error' is not defined
2025-08-25 13:53:34 ERROR root Failed to run callback function: Timert
Traceback (most recent call last):
  File "/main.py", line 13, in t
    print(error)
NameError: name 'error' is not defined
2025-08-25 13:53:35 ERROR root Failed to run callback function: Timert
Traceback (most recent call last):
  File "/main.py", line 13, in t
    print(error)
NameError: name 'error' is not defined
2025-08-25 13:53:36 ERROR root Failed to run callback function: Timert
Traceback (most recent call last):
  File "/main.py", line 13, in t
    print(error)
NameError: name 'error' is not defined
2025-08-25 13:53:37 ERROR root Failed to run callback function: Timert
Traceback (most recent call last):
  File "/main.py", line 13, in t
    print(error)
NameError: name 'error' is not defined
2025-08-25 13:53:38 ERROR root Failed to run callback function: Timert
Traceback (most recent call last):
  File "/main.py", line 13, in t
    print(error)
NameError: name 'error' is not defined
2025-08-25 13:53:39 ERROR root Failed to run callback function: Timert
Traceback (most recent call last):
  File "/main.py", line 13, in t
    print(error)
NameError: name 'error' is not defined
2025-08-25 13:53:40 ERROR root Failed to run callback function: Timert
Traceback (most recent call last):
  File "/main.py", line 13, in t
    print(error)
NameError: name 'error' is not defined
2025-08-25 13:53:41 ERROR root Failed to run callback function: Timert
Traceback (most recent call last):
  File "/main.py", line 13, in t
    print(error)
NameError: name 'error' is not defined
2025-08-25 13:53:42 ERROR root Failed to run callback function: Timert
Traceback (most recent call last):
  File "/main.py", line 13, in t
    print(error)
NameError: name 'error' is not defined
2025-08-25 13:53:43 ERROR root Failed to run callback function: Timert
Traceback (most recent call last):
  File "/main.py", line 13, in t
    print(error)
NameError: name 'error' is not defined
2025-08-25 13:53:44 ERROR root EXCEPTION:__InterfaceWrapper:Update:Projector:Traceback (most recent call last):
  File "c:\Users\manyr\OneDrive\Desktop\RD\ExtronServer\ServerLib\source\tools.py", line 1464, in __replacement_update
    method(None, qualifier)
  File "c:\Users\manyr\OneDrive\Desktop\RD\ExtronServer\ServerLib\source\opto_vp_UHD60_v1_0_1_0.py", line 193, in UpdatePower
    res = self.__UpdateHelper('Power', PowerCmdString, value, qualifier)
  File "c:\Users\manyr\OneDrive\Desktop\RD\ExtronServer\ServerLib\source\opto_vp_UHD60_v1_0_1_0.py", line 261, in __UpdateHelper
    res = self.SendAndWait(commandstring, self.DefaultResponseTimeout, deliTag=b'\r')
  File "c:\Users\manyr\OneDrive\Desktop\RD\ExtronServer\ServerLib\source\tools.py", line 1494, in SendAndWait
    ret = self.__interface.SendAndWait(commandstring,timeout,**args)
  File "c:\Users\manyr\OneDrive\Desktop\RD\ExtronServer\ServerLib\source\extronlib\interface\EthernetClientInterface.py", line 658, in SendAndWait
    return self.__ECI.SendAndWait(data,timeout,deliTag,deliRex,deliLen)
  File "c:\Users\manyr\OneDrive\Desktop\RD\ExtronServer\ServerLib\source\extronlib\interface\EthernetClientInterface.py", line 202, in SendAndWait
    return base64.b64decode(res)
  File "c:\Python\Python310\lib\base64.py", line 80, in b64decode
    s = _bytes_from_decode_data(s)
  File "c:\Python\Python310\lib\base64.py", line 45, in _bytes_from_decode_data
    raise TypeError("argument should be a bytes-like object or ASCII "
TypeError: argument should be a bytes-like object or ASCII string, not 'NoneType'

2025-08-25 13:53:44 ERROR root Failed to run callback function: Timert
Traceback (most recent call last):
  File "/main.py", line 13, in t
    print(error)
NameError: name 'error' is not defined
2025-08-25 13:53:45 ERROR root Failed to run callback function: Timert
Traceback (most recent call last):
  File "/main.py", line 13, in t
    print(error)
NameError: name 'error' is not defined
2025-08-25 13:53:46 ERROR root Failed to run callback function: Timert
Traceback (most recent call last):
  File "/main.py", line 13, in t
    print(error)
NameError: name 'error' is not defined
2025-08-25 13:53:47 ERROR root Failed to run callback function: Timert
Traceback (most recent call last):
  File "/main.py", line 13, in t
    print(error)
NameError: name 'error' is not defined
2025-08-25 13:53:48 ERROR root Failed to run callback function: Timert
Traceback (most recent call last):
  File "/main.py", line 13, in t
    print(error)
NameError: name 'error' is not defined
2025-08-25 13:53:49 ERROR root Failed to run callback function: Timert
Traceback (most recent call last):
  File "/main.py", line 13, in t
    print(error)
NameError: name 'error' is not defined
2025-08-25 13:53:51 ERROR root Failed to run callback function: Timert
Traceback (most recent call last):
  File "/main.py", line 13, in t
    print(error)
NameError: name 'error' is not defined
2025-08-25 13:53:52 ERROR root Failed to run callback function: Timert
Traceback (most recent call last):
  File "/main.py", line 13, in t
    print(error)
NameError: name 'error' is not defined
2025-08-25 13:53:53 ERROR root Failed to run callback function: Timert
Traceback (most recent call last):
  File "/main.py", line 13, in t
    print(error)
NameError: name 'error' is not defined
2025-08-25 13:53:54 ERROR root Failed to run callback function: Timert
Traceback (most recent call last):
  File "/main.py", line 13, in t
    print(error)
NameError: name 'error' is not defined
2025-08-25 13:53:54 ERROR root EthernetClient 192.168.1.244:2023 - Ethernet port not connected
2025-08-25 13:53:54 ERROR root EXCEPTION:__InterfaceWrapper:Update:Projector:Traceback (most recent call last):
  File "c:\Users\manyr\OneDrive\Desktop\RD\ExtronServer\ServerLib\source\tools.py", line 1464, in __replacement_update
    method(None, qualifier)
  File "c:\Users\manyr\OneDrive\Desktop\RD\ExtronServer\ServerLib\source\opto_vp_UHD60_v1_0_1_0.py", line 193, in UpdatePower
    res = self.__UpdateHelper('Power', PowerCmdString, value, qualifier)
  File "c:\Users\manyr\OneDrive\Desktop\RD\ExtronServer\ServerLib\source\opto_vp_UHD60_v1_0_1_0.py", line 261, in __UpdateHelper
    res = self.SendAndWait(commandstring, self.DefaultResponseTimeout, deliTag=b'\r')
  File "c:\Users\manyr\OneDrive\Desktop\RD\ExtronServer\ServerLib\source\tools.py", line 1494, in SendAndWait
    ret = self.__interface.SendAndWait(commandstring,timeout,**args)
  File "c:\Users\manyr\OneDrive\Desktop\RD\ExtronServer\ServerLib\source\extronlib\interface\EthernetClientInterface.py", line 658, in SendAndWait
    return self.__ECI.SendAndWait(data,timeout,deliTag,deliRex,deliLen)
  File "c:\Users\manyr\OneDrive\Desktop\RD\ExtronServer\ServerLib\source\extronlib\interface\EthernetClientInterface.py", line 202, in SendAndWait
    return base64.b64decode(res)
  File "c:\Python\Python310\lib\base64.py", line 80, in b64decode
    s = _bytes_from_decode_data(s)
  File "c:\Python\Python310\lib\base64.py", line 45, in _bytes_from_decode_data
    raise TypeError("argument should be a bytes-like object or ASCII "
TypeError: argument should be a bytes-like object or ASCII string, not 'NoneType'

2025-08-25 13:53:55 ERROR root Failed to run callback function: Timert
Traceback (most recent call last):
  File "/main.py", line 13, in t
    print(error)
NameError: name 'error' is not defined
2025-08-25 13:53:56 ERROR root Failed to run callback function: Timert
Traceback (most recent call last):
  File "/main.py", line 13, in t
    print(error)
NameError: name 'error' is not defined
2025-08-25 13:53:57 ERROR root Failed to run callback function: Timert
Traceback (most recent call last):
  File "/main.py", line 13, in t
    print(error)
NameError: name 'error' is not defined
2025-08-25 13:53:58 ERROR root Failed to run callback function: Timert
Traceback (most recent call last):
  File "/main.py", line 13, in t
    print(error)
NameError: name 'error' is not defined
2025-08-25 13:53:59 ERROR root Failed to run callback function: Timert
Traceback (most recent call last):
  File "/main.py", line 13, in t
    print(error)
NameError: name 'error' is not defined
2025-08-25 13:54:00 ERROR root Failed to run callback function: Timert
Traceback (most recent call last):
  File "/main.py", line 13, in t
    print(error)
NameError: name 'error' is not defined
2025-08-25 13:54:01 ERROR root Failed to run callback function: Timert
Traceback (most recent call last):
  File "/main.py", line 13, in t
    print(error)
NameError: name 'error' is not defined
2025-08-25 13:54:02 ERROR root Failed to run callback function: Timert
Traceback (most recent call last):
  File "/main.py", line 13, in t
    print(error)
NameError: name 'error' is not defined
2025-08-25 13:54:03 ERROR root Failed to run callback function: Timert
Traceback (most recent call last):
  File "/main.py", line 13, in t
    print(error)
NameError: name 'error' is not defined
2025-08-25 13:54:04 ERROR root Failed to run callback function: Timert
Traceback (most recent call last):
  File "/main.py", line 13, in t
    print(error)
NameError: name 'error' is not defined
2025-08-25 13:54:05 ERROR root Failed to run callback function: Timert
Traceback (most recent call last):
  File "/main.py", line 13, in t
    print(error)
NameError: name 'error' is not defined
2025-08-25 13:54:06 ERROR root Failed to run callback function: Timert
Traceback (most recent call last):
  File "/main.py", line 13, in t
    print(error)
NameError: name 'error' is not defined
2025-08-25 13:54:06 ERROR root Receive failed, from client
2025-08-25 13:54:07 ERROR root Failed to run callback function: Timert
Traceback (most recent call last):
  File "/main.py", line 13, in t
    print(error)
NameError: name 'error' is not defined
2025-08-25 13:54:08 ERROR root Failed to run callback function: Timert
Traceback (most recent call last):
  File "/main.py", line 13, in t
    print(error)
NameError: name 'error' is not defined
2025-08-25 13:54:09 ERROR root Failed to run callback function: Timert
Traceback (most recent call last):
  File "/main.py", line 13, in t
    print(error)
NameError: name 'error' is not defined
2025-08-25 13:54:10 ERROR root Failed to run callback function: Timert
Traceback (most recent call last):
  File "/main.py", line 13, in t
    print(error)
NameError: name 'error' is not defined
2025-08-25 13:54:11 ERROR root Failed to run callback function: Timert
Traceback (most recent call last):
  File "/main.py", line 13, in t
    print(error)
NameError: name 'error' is not defined
2025-08-25 13:54:12 ERROR root Failed to run callback function: Timert
Traceback (most recent call last):
  File "/main.py", line 13, in t
    print(error)
NameError: name 'error' is not defined
2025-08-25 13:54:13 ERROR root Failed to run callback function: Timert
Traceback (most recent call last):
  File "/main.py", line 13, in t
    print(error)
NameError: name 'error' is not defined
2025-08-25 13:54:14 ERROR root Failed to run callback function: Timert
Traceback (most recent call last):
  File "/main.py", line 13, in t
    print(error)
NameError: name 'error' is not defined
2025-08-25 13:54:15 ERROR root Failed to run callback function: Timert
Traceback (most recent call last):
  File "/main.py", line 13, in t
    print(error)
NameError: name 'error' is not defined
2025-08-25 13:54:16 ERROR root Failed to run callback function: Timert
Traceback (most recent call last):
  File "/main.py", line 13, in t
    print(error)
NameError: name 'error' is not defined
2025-08-25 13:54:17 ERROR root Failed to run callback function: Timert
Traceback (most recent call last):
  File "/main.py", line 13, in t
    print(error)
NameError: name 'error' is not defined
2025-08-25 13:54:18 ERROR root Failed to run callback function: Timert
Traceback (most recent call last):
  File "/main.py", line 13, in t
    print(error)
NameError: name 'error' is not defined
2025-08-25 13:54:19 ERROR root Failed to run callback function: Timert
Traceback (most recent call last):
  File "/main.py", line 13, in t
    print(error)
NameError: name 'error' is not defined
2025-08-25 13:54:20 ERROR root Failed to run callback function: Timert
Traceback (most recent call last):
  File "/main.py", line 13, in t
    print(error)
NameError: name 'error' is not defined
2025-08-25 13:54:21 ERROR root Failed to run callback function: Timert
Traceback (most recent call last):
  File "/main.py", line 13, in t
    print(error)
NameError: name 'error' is not defined
2025-08-25 13:54:22 ERROR root Failed to run callback function: Timert
Traceback (most recent call last):
  File "/main.py", line 13, in t
    print(error)
NameError: name 'error' is not defined
2025-08-25 13:54:23 ERROR root Failed to run callback function: Timert
Traceback (most recent call last):
  File "/main.py", line 13, in t
    print(error)
NameError: name 'error' is not defined
2025-08-25 13:54:24 ERROR root Failed to run callback function: Timert
Traceback (most recent call last):
  File "/main.py", line 13, in t
    print(error)
NameError: name 'error' is not defined
2025-08-25 13:54:25 ERROR root Failed to run callback function: Timert
Traceback (most recent call last):
  File "/main.py", line 13, in t
    print(error)
NameError: name 'error' is not defined
2025-08-25 13:54:26 ERROR root Failed to run callback function: Timert
Traceback (most recent call last):
  File "/main.py", line 13, in t
    print(error)
NameError: name 'error' is not defined
2025-08-25 13:54:27 ERROR root Failed to run callback function: Timert
Traceback (most recent call last):
  File "/main.py", line 13, in t
    print(error)
NameError: name 'error' is not defined
2025-08-25 13:54:28 ERROR root Failed to run callback function: Timert
Traceback (most recent call last):
  File "/main.py", line 13, in t
    print(error)
NameError: name 'error' is not defined
2025-08-25 13:54:29 ERROR root Failed to run callback function: Timert
Traceback (most recent call last):
  File "/main.py", line 13, in t
    print(error)
NameError: name 'error' is not defined
2025-08-25 13:54:30 ERROR root Failed to run callback function: Timert
Traceback (most recent call last):
  File "/main.py", line 13, in t
    print(error)
NameError: name 'error' is not defined
2025-08-25 13:54:31 ERROR root Failed to run callback function: Timert
Traceback (most recent call last):
  File "/main.py", line 13, in t
    print(error)
NameError: name 'error' is not defined
2025-08-25 13:54:32 ERROR root Failed to run callback function: Timert
Traceback (most recent call last):
  File "/main.py", line 13, in t
    print(error)
NameError: name 'error' is not defined
2025-08-25 13:54:33 ERROR root Failed to run callback function: Timert
Traceback (most recent call last):
  File "/main.py", line 13, in t
    print(error)
NameError: name 'error' is not defined
2025-08-25 13:54:34 ERROR root Failed to run callback function: Timert
Traceback (most recent call last):
  File "/main.py", line 13, in t
    print(error)
NameError: name 'error' is not defined
2025-08-25 13:54:35 ERROR root Failed to run callback function: Timert
Traceback (most recent call last):
  File "/main.py", line 13, in t
    print(error)
NameError: name 'error' is not defined
2025-08-25 13:54:36 ERROR root Failed to run callback function: Timert
Traceback (most recent call last):
  File "/main.py", line 13, in t
    print(error)
NameError: name 'error' is not defined
2025-08-25 13:54:37 ERROR root Failed to run callback function: Timert
Traceback (most recent call last):
  File "/main.py", line 13, in t
    print(error)
NameError: name 'error' is not defined
2025-08-25 13:54:38 ERROR root Failed to run callback function: Timert
Traceback (most recent call last):
  File "/main.py", line 13, in t
    print(error)
NameError: name 'error' is not defined
2025-08-25 13:54:39 ERROR root Failed to run callback function: Timert
Traceback (most recent call last):
  File "/main.py", line 13, in t
    print(error)
NameError: name 'error' is not defined
2025-08-25 13:54:40 ERROR root Failed to run callback function: Timert
Traceback (most recent call last):
  File "/main.py", line 13, in t
    print(error)
NameError: name 'error' is not defined
2025-08-25 13:54:41 ERROR root Failed to run callback function: Timert
Traceback (most recent call last):
  File "/main.py", line 13, in t
    print(error)
NameError: name 'error' is not defined
2025-08-25 13:54:42 ERROR root Failed to run callback function: Timert
Traceback (most recent call last):
  File "/main.py", line 13, in t
    print(error)
NameError: name 'error' is not defined
2025-08-25 13:54:43 ERROR root Failed to run callback function: Timert
Traceback (most recent call last):
  File "/main.py", line 13, in t
    print(error)
NameError: name 'error' is not defined
2025-08-25 13:54:44 ERROR root Failed to run callback function: Timert
Traceback (most recent call last):
  File "/main.py", line 13, in t
    print(error)
NameError: name 'error' is not defined
2025-08-25 13:54:45 ERROR root Failed to run callback function: Timert
Traceback (most recent call last):
  File "/main.py", line 13, in t
    print(error)
NameError: name 'error' is not defined
2025-08-25 13:54:46 ERROR root Failed to run callback function: Timert
Traceback (most recent call last):
  File "/main.py", line 13, in t
    print(error)
NameError: name 'error' is not defined
2025-08-25 13:54:47 ERROR root Failed to run callback function: Timert
Traceback (most recent call last):
  File "/main.py", line 13, in t
    print(error)
NameError: name 'error' is not defined
2025-08-25 13:54:48 ERROR root Failed to run callback function: Timert
Traceback (most recent call last):
  File "/main.py", line 13, in t
    print(error)
NameError: name 'error' is not defined
2025-08-25 13:54:49 ERROR root Failed to run callback function: Timert
Traceback (most recent call last):
  File "/main.py", line 13, in t
    print(error)
NameError: name 'error' is not defined
2025-08-25 13:54:50 ERROR root Failed to run callback function: Timert
Traceback (most recent call last):
  File "/main.py", line 13, in t
    print(error)
NameError: name 'error' is not defined
2025-08-25 13:54:51 ERROR root Failed to run callback function: Timert
Traceback (most recent call last):
  File "/main.py", line 13, in t
    print(error)
NameError: name 'error' is not defined
2025-08-25 13:54:52 ERROR root Failed to run callback function: Timert
Traceback (most recent call last):
  File "/main.py", line 13, in t
    print(error)
NameError: name 'error' is not defined
2025-08-25 13:54:53 ERROR root Failed to run callback function: Timert
Traceback (most recent call last):
  File "/main.py", line 13, in t
    print(error)
NameError: name 'error' is not defined
2025-08-25 13:54:54 ERROR root Failed to run callback function: Timert
Traceback (most recent call last):
  File "/main.py", line 13, in t
    print(error)
NameError: name 'error' is not defined
2025-08-25 13:54:55 ERROR root Failed to run callback function: Timert
Traceback (most recent call last):
  File "/main.py", line 13, in t
    print(error)
NameError: name 'error' is not defined
2025-08-25 13:54:56 ERROR root Failed to run callback function: Timert
Traceback (most recent call last):
  File "/main.py", line 13, in t
    print(error)
NameError: name 'error' is not defined
2025-08-25 13:54:57 ERROR root Failed to run callback function: Timert
Traceback (most recent call last):
  File "/main.py", line 13, in t
    print(error)
NameError: name 'error' is not defined
2025-08-25 13:54:58 ERROR root Failed to run callback function: Timert
Traceback (most recent call last):
  File "/main.py", line 13, in t
    print(error)
NameError: name 'error' is not defined
2025-08-25 13:54:59 ERROR root Failed to run callback function: Timert
Traceback (most recent call last):
  File "/main.py", line 13, in t
    print(error)
NameError: name 'error' is not defined
2025-08-25 13:55:00 ERROR root Failed to run callback function: Timert
Traceback (most recent call last):
  File "/main.py", line 13, in t
    print(error)
NameError: name 'error' is not defined
2025-08-25 13:55:01 ERROR root Failed to run callback function: Timert
Traceback (most recent call last):
  File "/main.py", line 13, in t
    print(error)
NameError: name 'error' is not defined
2025-08-25 13:55:02 ERROR root Failed to run callback function: Timert
Traceback (most recent call last):
  File "/main.py", line 13, in t
    print(error)
NameError: name 'error' is not defined
2025-08-25 13:55:03 ERROR root Failed to run callback function: Timert
Traceback (most recent call last):
  File "/main.py", line 13, in t
    print(error)
NameError: name 'error' is not defined
2025-08-25 13:55:04 ERROR root Failed to run callback function: Timert
Traceback (most recent call last):
  File "/main.py", line 13, in t
    print(error)
NameError: name 'error' is not defined
2025-08-25 13:55:05 ERROR root Failed to run callback function: Timert
Traceback (most recent call last):
  File "/main.py", line 13, in t
    print(error)
NameError: name 'error' is not defined
2025-08-25 13:55:06 ERROR root Failed to run callback function: Timert
Traceback (most recent call last):
  File "/main.py", line 13, in t
    print(error)
NameError: name 'error' is not defined
2025-08-25 13:55:07 ERROR root Failed to run callback function: Timert
Traceback (most recent call last):
  File "/main.py", line 13, in t
    print(error)
NameError: name 'error' is not defined
2025-08-25 13:55:08 ERROR root Failed to run callback function: Timert
Traceback (most recent call last):
  File "/main.py", line 13, in t
    print(error)
NameError: name 'error' is not defined
2025-08-25 13:55:09 ERROR root Failed to run callback function: Timert
Traceback (most recent call last):
  File "/main.py", line 13, in t
    print(error)
NameError: name 'error' is not defined
2025-08-25 13:55:10 ERROR root Failed to run callback function: Timert
Traceback (most recent call last):
  File "/main.py", line 13, in t
    print(error)
NameError: name 'error' is not defined
2025-08-25 13:55:11 ERROR root Failed to run callback function: Timert
Traceback (most recent call last):
  File "/main.py", line 13, in t
    print(error)
NameError: name 'error' is not defined
2025-08-25 13:55:12 ERROR root Failed to run callback function: Timert
Traceback (most recent call last):
  File "/main.py", line 13, in t
    print(error)
NameError: name 'error' is not defined
2025-08-25 13:55:13 ERROR root Failed to run callback function: Timert
Traceback (most recent call last):
  File "/main.py", line 13, in t
    print(error)
NameError: name 'error' is not defined
2025-08-25 13:55:14 ERROR root Failed to run callback function: Timert
Traceback (most recent call last):
  File "/main.py", line 13, in t
    print(error)
NameError: name 'error' is not defined
2025-08-25 13:55:15 ERROR root Failed to run callback function: Timert
Traceback (most recent call last):
  File "/main.py", line 13, in t
    print(error)
NameError: name 'error' is not defined
2025-08-25 13:55:16 ERROR root Failed to run callback function: Timert
Traceback (most recent call last):
  File "/main.py", line 13, in t
    print(error)
NameError: name 'error' is not defined
2025-08-25 13:55:17 ERROR root Failed to run callback function: Timert
Traceback (most recent call last):
  File "/main.py", line 13, in t
    print(error)
NameError: name 'error' is not defined
2025-08-25 13:55:18 ERROR root Failed to run callback function: Timert
Traceback (most recent call last):
  File "/main.py", line 13, in t
    print(error)
NameError: name 'error' is not defined
2025-08-25 13:55:20 ERROR root Failed to run callback function: Timert
Traceback (most recent call last):
  File "/main.py", line 13, in t
    print(error)
NameError: name 'error' is not defined
2025-08-25 13:55:21 ERROR root Failed to run callback function: Timert
Traceback (most recent call last):
  File "/main.py", line 13, in t
    print(error)
NameError: name 'error' is not defined
2025-08-25 13:55:22 ERROR root Failed to run callback function: Timert
Traceback (most recent call last):
  File "/main.py", line 13, in t
    print(error)
NameError: name 'error' is not defined
2025-08-25 13:55:23 ERROR root Failed to run callback function: Timert
Traceback (most recent call last):
  File "/main.py", line 13, in t
    print(error)
NameError: name 'error' is not defined
2025-08-25 13:55:24 ERROR root Failed to run callback function: Timert
Traceback (most recent call last):
  File "/main.py", line 13, in t
    print(error)
NameError: name 'error' is not defined
2025-08-25 13:55:25 ERROR root Failed to run callback function: Timert
Traceback (most recent call last):
  File "/main.py", line 13, in t
    print(error)
NameError: name 'error' is not defined
2025-08-25 13:55:26 ERROR root Failed to run callback function: Timert
Traceback (most recent call last):
  File "/main.py", line 13, in t
    print(error)
NameError: name 'error' is not defined
2025-08-25 13:55:27 ERROR root Failed to run callback function: Timert
Traceback (most recent call last):
  File "/main.py", line 13, in t
    print(error)
NameError: name 'error' is not defined
2025-08-25 13:55:28 ERROR root Failed to run callback function: Timert
Traceback (most recent call last):
  File "/main.py", line 13, in t
    print(error)
NameError: name 'error' is not defined
2025-08-25 13:55:29 ERROR root Failed to run callback function: Timert
Traceback (most recent call last):
  File "/main.py", line 13, in t
    print(error)
NameError: name 'error' is not defined
2025-08-25 13:55:30 ERROR root Failed to run callback function: Timert
Traceback (most recent call last):
  File "/main.py", line 13, in t
    print(error)
NameError: name 'error' is not defined
2025-08-25 13:55:31 ERROR root Failed to run callback function: Timert
Traceback (most recent call last):
  File "/main.py", line 13, in t
    print(error)
NameError: name 'error' is not defined
2025-08-25 13:55:32 ERROR root Failed to run callback function: Timert
Traceback (most recent call last):
  File "/main.py", line 13, in t
    print(error)
NameError: name 'error' is not defined
2025-08-25 13:55:33 ERROR root Failed to run callback function: Timert
Traceback (most recent call last):
  File "/main.py", line 13, in t
    print(error)
NameError: name 'error' is not defined
2025-08-25 13:55:34 ERROR root Failed to run callback function: Timert
Traceback (most recent call last):
  File "/main.py", line 13, in t
    print(error)
NameError: name 'error' is not defined
2025-08-25 13:55:35 ERROR root Failed to run callback function: Timert
Traceback (most recent call last):
  File "/main.py", line 13, in t
    print(error)
NameError: name 'error' is not defined
2025-08-25 13:55:36 ERROR root Failed to run callback function: Timert
Traceback (most recent call last):
  File "/main.py", line 13, in t
    print(error)
NameError: name 'error' is not defined
2025-08-25 13:55:37 ERROR root Failed to run callback function: Timert
Traceback (most recent call last):
  File "/main.py", line 13, in t
    print(error)
NameError: name 'error' is not defined
2025-08-25 13:55:38 ERROR root Failed to run callback function: Timert
Traceback (most recent call last):
  File "/main.py", line 13, in t
    print(error)
NameError: name 'error' is not defined
2025-08-25 13:55:39 ERROR root Failed to run callback function: Timert
Traceback (most recent call last):
  File "/main.py", line 13, in t
    print(error)
NameError: name 'error' is not defined
2025-08-25 13:55:40 ERROR root Failed to run callback function: Timert
Traceback (most recent call last):
  File "/main.py", line 13, in t
    print(error)
NameError: name 'error' is not defined
2025-08-25 13:55:41 ERROR root Failed to run callback function: Timert
Traceback (most recent call last):
  File "/main.py", line 13, in t
    print(error)
NameError: name 'error' is not defined
2025-08-25 13:55:42 ERROR root Failed to run callback function: Timert
Traceback (most recent call last):
  File "/main.py", line 13, in t
    print(error)
NameError: name 'error' is not defined
2025-08-25 13:55:43 ERROR root Failed to run callback function: Timert
Traceback (most recent call last):
  File "/main.py", line 13, in t
    print(error)
NameError: name 'error' is not defined
2025-08-25 13:55:44 ERROR root Failed to run callback function: Timert
Traceback (most recent call last):
  File "/main.py", line 13, in t
    print(error)
NameError: name 'error' is not defined
2025-08-25 13:55:45 ERROR root Failed to run callback function: Timert
Traceback (most recent call last):
  File "/main.py", line 13, in t
    print(error)
NameError: name 'error' is not defined
2025-08-25 13:55:46 ERROR root Failed to run callback function: Timert
Traceback (most recent call last):
  File "/main.py", line 13, in t
    print(error)
NameError: name 'error' is not defined
2025-08-25 13:55:47 ERROR root Failed to run callback function: Timert
Traceback (most recent call last):
  File "/main.py", line 13, in t
    print(error)
NameError: name 'error' is not defined
2025-08-25 13:55:48 ERROR root Failed to run callback function: Timert
Traceback (most recent call last):
  File "/main.py", line 13, in t
    print(error)
NameError: name 'error' is not defined
2025-08-25 13:55:49 ERROR root Failed to run callback function: Timert
Traceback (most recent call last):
  File "/main.py", line 13, in t
    print(error)
NameError: name 'error' is not defined
2025-08-25 13:55:50 ERROR root Failed to run callback function: Timert
Traceback (most recent call last):
  File "/main.py", line 13, in t
    print(error)
NameError: name 'error' is not defined
2025-08-25 13:55:51 ERROR root Failed to run callback function: Timert
Traceback (most recent call last):
  File "/main.py", line 13, in t
    print(error)
NameError: name 'error' is not defined
2025-08-25 13:55:52 ERROR root Failed to run callback function: Timert
Traceback (most recent call last):
  File "/main.py", line 13, in t
    print(error)
NameError: name 'error' is not defined
2025-08-25 13:55:53 ERROR root Failed to run callback function: Timert
Traceback (most recent call last):
  File "/main.py", line 13, in t
    print(error)
NameError: name 'error' is not defined
2025-08-25 13:55:54 ERROR root Failed to run callback function: Timert
Traceback (most recent call last):
  File "/main.py", line 13, in t
    print(error)
NameError: name 'error' is not defined
2025-08-25 13:55:55 ERROR root Failed to run callback function: Timert
Traceback (most recent call last):
  File "/main.py", line 13, in t
    print(error)
NameError: name 'error' is not defined
2025-08-25 13:55:56 ERROR root Failed to run callback function: Timert
Traceback (most recent call last):
  File "/main.py", line 13, in t
    print(error)
NameError: name 'error' is not defined
2025-08-25 13:55:57 ERROR root Failed to run callback function: Timert
Traceback (most recent call last):
  File "/main.py", line 13, in t
    print(error)
NameError: name 'error' is not defined
2025-08-25 13:55:58 ERROR root Failed to run callback function: Timert
Traceback (most recent call last):
  File "/main.py", line 13, in t
    print(error)
NameError: name 'error' is not defined
2025-08-25 13:55:59 ERROR root Failed to run callback function: Timert
Traceback (most recent call last):
  File "/main.py", line 13, in t
    print(error)
NameError: name 'error' is not defined
2025-08-25 13:56:00 ERROR root Failed to run callback function: Timert
Traceback (most recent call last):
  File "/main.py", line 13, in t
    print(error)
NameError: name 'error' is not defined
2025-08-25 13:56:01 ERROR root Failed to run callback function: Timert
Traceback (most recent call last):
  File "/main.py", line 13, in t
    print(error)
NameError: name 'error' is not defined
2025-08-25 13:56:02 ERROR root Failed to run callback function: Timert
Traceback (most recent call last):
  File "/main.py", line 13, in t
    print(error)
NameError: name 'error' is not defined
2025-08-25 13:56:03 ERROR root Failed to run callback function: Timert
Traceback (most recent call last):
  File "/main.py", line 13, in t
    print(error)
NameError: name 'error' is not defined
2025-08-25 13:56:04 ERROR root Failed to run callback function: Timert
Traceback (most recent call last):
  File "/main.py", line 13, in t
    print(error)
NameError: name 'error' is not defined
2025-08-25 13:56:05 ERROR root Failed to run callback function: Timert
Traceback (most recent call last):
  File "/main.py", line 13, in t
    print(error)
NameError: name 'error' is not defined
2025-08-25 13:56:06 ERROR root Failed to run callback function: Timert
Traceback (most recent call last):
  File "/main.py", line 13, in t
    print(error)
NameError: name 'error' is not defined
2025-08-25 13:56:07 ERROR root Failed to run callback function: Timert
Traceback (most recent call last):
  File "/main.py", line 13, in t
    print(error)
NameError: name 'error' is not defined
2025-08-25 13:56:08 ERROR root Failed to run callback function: Timert
Traceback (most recent call last):
  File "/main.py", line 13, in t
    print(error)
NameError: name 'error' is not defined
2025-08-25 13:56:09 ERROR root Failed to run callback function: Timert
Traceback (most recent call last):
  File "/main.py", line 13, in t
    print(error)
NameError: name 'error' is not defined
2025-08-25 13:56:10 ERROR root Failed to run callback function: Timert
Traceback (most recent call last):
  File "/main.py", line 13, in t
    print(error)
NameError: name 'error' is not defined
2025-08-25 13:56:11 ERROR root Failed to run callback function: Timert
Traceback (most recent call last):
  File "/main.py", line 13, in t
    print(error)
NameError: name 'error' is not defined
2025-08-25 13:56:12 ERROR root Failed to run callback function: Timert
Traceback (most recent call last):
  File "/main.py", line 13, in t
    print(error)
NameError: name 'error' is not defined
2025-08-25 13:56:13 ERROR root Failed to run callback function: Timert
Traceback (most recent call last):
  File "/main.py", line 13, in t
    print(error)
NameError: name 'error' is not defined
2025-08-25 13:56:14 ERROR root Failed to run callback function: Timert
Traceback (most recent call last):
  File "/main.py", line 13, in t
    print(error)
NameError: name 'error' is not defined
2025-08-25 13:56:15 ERROR root Failed to run callback function: Timert
Traceback (most recent call last):
  File "/main.py", line 13, in t
    print(error)
NameError: name 'error' is not defined
2025-08-25 13:56:16 ERROR root Failed to run callback function: Timert
Traceback (most recent call last):
  File "/main.py", line 13, in t
    print(error)
NameError: name 'error' is not defined
2025-08-25 13:56:17 ERROR root Failed to run callback function: Timert
Traceback (most recent call last):
  File "/main.py", line 13, in t
    print(error)
NameError: name 'error' is not defined
2025-08-25 13:56:18 ERROR root Failed to run callback function: Timert
Traceback (most recent call last):
  File "/main.py", line 13, in t
    print(error)
NameError: name 'error' is not defined
2025-08-25 13:56:19 ERROR root Failed to run callback function: Timert
Traceback (most recent call last):
  File "/main.py", line 13, in t
    print(error)
NameError: name 'error' is not defined
2025-08-25 13:56:20 ERROR root Failed to run callback function: Timert
Traceback (most recent call last):
  File "/main.py", line 13, in t
    print(error)
NameError: name 'error' is not defined
2025-08-25 13:56:21 ERROR root Failed to run callback function: Timert
Traceback (most recent call last):
  File "/main.py", line 13, in t
    print(error)
NameError: name 'error' is not defined
2025-08-25 13:56:22 ERROR root Failed to run callback function: Timert
Traceback (most recent call last):
  File "/main.py", line 13, in t
    print(error)
NameError: name 'error' is not defined
2025-08-25 13:56:23 ERROR root Failed to run callback function: Timert
Traceback (most recent call last):
  File "/main.py", line 13, in t
    print(error)
NameError: name 'error' is not defined
2025-08-25 13:56:24 ERROR root Failed to run callback function: Timert
Traceback (most recent call last):
  File "/main.py", line 13, in t
    print(error)
NameError: name 'error' is not defined
2025-08-25 13:56:25 ERROR root Failed to run callback function: Timert
Traceback (most recent call last):
  File "/main.py", line 13, in t
    print(error)
NameError: name 'error' is not defined
2025-08-25 13:56:26 ERROR root Failed to run callback function: Timert
Traceback (most recent call last):
  File "/main.py", line 13, in t
    print(error)
NameError: name 'error' is not defined
2025-08-25 13:56:27 ERROR root Failed to run callback function: Timert
Traceback (most recent call last):
  File "/main.py", line 13, in t
    print(error)
NameError: name 'error' is not defined
2025-08-25 13:56:28 ERROR root Failed to run callback function: Timert
Traceback (most recent call last):
  File "/main.py", line 13, in t
    print(error)
NameError: name 'error' is not defined
2025-08-25 13:56:29 ERROR root Failed to run callback function: Timert
Traceback (most recent call last):
  File "/main.py", line 13, in t
    print(error)
NameError: name 'error' is not defined
2025-08-25 13:56:30 ERROR root Failed to run callback function: Timert
Traceback (most recent call last):
  File "/main.py", line 13, in t
    print(error)
NameError: name 'error' is not defined
2025-08-25 13:56:31 ERROR root Failed to run callback function: Timert
Traceback (most recent call last):
  File "/main.py", line 13, in t
    print(error)
NameError: name 'error' is not defined
2025-08-25 13:56:32 ERROR root Failed to run callback function: Timert
Traceback (most recent call last):
  File "/main.py", line 13, in t
    print(error)
NameError: name 'error' is not defined
2025-08-25 13:56:33 ERROR root Failed to run callback function: Timert
Traceback (most recent call last):
  File "/main.py", line 13, in t
    print(error)
NameError: name 'error' is not defined
2025-08-25 13:56:34 ERROR root Failed to run callback function: Timert
Traceback (most recent call last):
  File "/main.py", line 13, in t
    print(error)
NameError: name 'error' is not defined
2025-08-25 13:56:35 ERROR root Failed to run callback function: Timert
Traceback (most recent call last):
  File "/main.py", line 13, in t
    print(error)
NameError: name 'error' is not defined
2025-08-25 13:56:36 ERROR root Failed to run callback function: Timert
Traceback (most recent call last):
  File "/main.py", line 13, in t
    print(error)
NameError: name 'error' is not defined
2025-08-25 13:56:37 ERROR root Failed to run callback function: Timert
Traceback (most recent call last):
  File "/main.py", line 13, in t
    print(error)
NameError: name 'error' is not defined
2025-08-25 13:56:38 ERROR root Failed to run callback function: Timert
Traceback (most recent call last):
  File "/main.py", line 13, in t
    print(error)
NameError: name 'error' is not defined
2025-08-25 13:56:39 ERROR root Failed to run callback function: Timert
Traceback (most recent call last):
  File "/main.py", line 13, in t
    print(error)
NameError: name 'error' is not defined
2025-08-25 13:56:40 ERROR root Failed to run callback function: Timert
Traceback (most recent call last):
  File "/main.py", line 13, in t
    print(error)
NameError: name 'error' is not defined
2025-08-25 13:56:41 ERROR root Failed to run callback function: Timert
Traceback (most recent call last):
  File "/main.py", line 13, in t
    print(error)
NameError: name 'error' is not defined
2025-08-25 13:56:42 ERROR root Failed to run callback function: Timert
Traceback (most recent call last):
  File "/main.py", line 13, in t
    print(error)
NameError: name 'error' is not defined
2025-08-25 13:56:43 ERROR root Failed to run callback function: Timert
Traceback (most recent call last):
  File "/main.py", line 13, in t
    print(error)
NameError: name 'error' is not defined
2025-08-25 13:56:44 ERROR root Failed to run callback function: Timert
Traceback (most recent call last):
  File "/main.py", line 13, in t
    print(error)
NameError: name 'error' is not defined
2025-08-25 13:56:45 ERROR root Failed to run callback function: Timert
Traceback (most recent call last):
  File "/main.py", line 13, in t
    print(error)
NameError: name 'error' is not defined
2025-08-25 13:56:46 ERROR root Failed to run callback function: Timert
Traceback (most recent call last):
  File "/main.py", line 13, in t
    print(error)
NameError: name 'error' is not defined
2025-08-25 13:56:47 ERROR root Failed to run callback function: Timert
Traceback (most recent call last):
  File "/main.py", line 13, in t
    print(error)
NameError: name 'error' is not defined
2025-08-25 13:56:48 ERROR root Failed to run callback function: Timert
Traceback (most recent call last):
  File "/main.py", line 13, in t
    print(error)
NameError: name 'error' is not defined
2025-08-25 13:56:50 ERROR root Failed to run callback function: Timert
Traceback (most recent call last):
  File "/main.py", line 13, in t
    print(error)
NameError: name 'error' is not defined
2025-08-25 13:56:51 ERROR root Failed to run callback function: Timert
Traceback (most recent call last):
  File "/main.py", line 13, in t
    print(error)
NameError: name 'error' is not defined
2025-08-25 13:56:52 ERROR root Failed to run callback function: Timert
Traceback (most recent call last):
  File "/main.py", line 13, in t
    print(error)
NameError: name 'error' is not defined
2025-08-25 13:56:53 ERROR root Failed to run callback function: Timert
Traceback (most recent call last):
  File "/main.py", line 13, in t
    print(error)
NameError: name 'error' is not defined
2025-08-25 13:56:54 ERROR root Failed to run callback function: Timert
Traceback (most recent call last):
  File "/main.py", line 13, in t
    print(error)
NameError: name 'error' is not defined
2025-08-25 13:56:55 ERROR root Failed to run callback function: Timert
Traceback (most recent call last):
  File "/main.py", line 13, in t
    print(error)
NameError: name 'error' is not defined
2025-08-25 13:56:56 ERROR root Failed to run callback function: Timert
Traceback (most recent call last):
  File "/main.py", line 13, in t
    print(error)
NameError: name 'error' is not defined
2025-08-25 13:56:57 ERROR root Failed to run callback function: Timert
Traceback (most recent call last):
  File "/main.py", line 13, in t
    print(error)
NameError: name 'error' is not defined
2025-08-25 13:56:58 ERROR root Failed to run callback function: Timert
Traceback (most recent call last):
  File "/main.py", line 13, in t
    print(error)
NameError: name 'error' is not defined
2025-08-25 13:56:59 ERROR root Failed to run callback function: Timert
Traceback (most recent call last):
  File "/main.py", line 13, in t
    print(error)
NameError: name 'error' is not defined
2025-08-25 13:57:00 ERROR root Failed to run callback function: Timert
Traceback (most recent call last):
  File "/main.py", line 13, in t
    print(error)
NameError: name 'error' is not defined
2025-08-25 13:57:01 ERROR root Failed to run callback function: Timert
Traceback (most recent call last):
  File "/main.py", line 13, in t
    print(error)
NameError: name 'error' is not defined
2025-08-25 13:57:02 ERROR root Failed to run callback function: Timert
Traceback (most recent call last):
  File "/main.py", line 13, in t
    print(error)
NameError: name 'error' is not defined
2025-08-25 13:57:03 ERROR root Failed to run callback function: Timert
Traceback (most recent call last):
  File "/main.py", line 13, in t
    print(error)
NameError: name 'error' is not defined
2025-08-25 13:57:04 ERROR root Failed to run callback function: Timert
Traceback (most recent call last):
  File "/main.py", line 13, in t
    print(error)
NameError: name 'error' is not defined
2025-08-25 13:57:05 ERROR root Failed to run callback function: Timert
Traceback (most recent call last):
  File "/main.py", line 13, in t
    print(error)
NameError: name 'error' is not defined
2025-08-25 13:57:06 ERROR root Failed to run callback function: Timert
Traceback (most recent call last):
  File "/main.py", line 13, in t
    print(error)
NameError: name 'error' is not defined
2025-08-25 13:57:07 ERROR root Failed to run callback function: Timert
Traceback (most recent call last):
  File "/main.py", line 13, in t
    print(error)
NameError: name 'error' is not defined
2025-08-25 13:57:08 ERROR root Failed to run callback function: Timert
Traceback (most recent call last):
  File "/main.py", line 13, in t
    print(error)
NameError: name 'error' is not defined
2025-08-25 13:57:09 ERROR root Failed to run callback function: Timert
Traceback (most recent call last):
  File "/main.py", line 13, in t
    print(error)
NameError: name 'error' is not defined
2025-08-25 13:57:10 ERROR root Failed to run callback function: Timert
Traceback (most recent call last):
  File "/main.py", line 13, in t
    print(error)
NameError: name 'error' is not defined
2025-08-25 13:57:11 ERROR root Failed to run callback function: Timert
Traceback (most recent call last):
  File "/main.py", line 13, in t
    print(error)
NameError: name 'error' is not defined
2025-08-25 13:57:12 ERROR root Failed to run callback function: Timert
Traceback (most recent call last):
  File "/main.py", line 13, in t
    print(error)
NameError: name 'error' is not defined
2025-08-25 13:57:13 ERROR root Failed to run callback function: Timert
Traceback (most recent call last):
  File "/main.py", line 13, in t
    print(error)
NameError: name 'error' is not defined
2025-08-25 13:57:14 ERROR root Failed to run callback function: Timert
Traceback (most recent call last):
  File "/main.py", line 13, in t
    print(error)
NameError: name 'error' is not defined
2025-08-25 13:57:15 ERROR root Failed to run callback function: Timert
Traceback (most recent call last):
  File "/main.py", line 13, in t
    print(error)
NameError: name 'error' is not defined
2025-08-25 13:57:16 ERROR root Failed to run callback function: Timert
Traceback (most recent call last):
  File "/main.py", line 13, in t
    print(error)
NameError: name 'error' is not defined
2025-08-25 13:57:17 ERROR root Failed to run callback function: Timert
Traceback (most recent call last):
  File "/main.py", line 13, in t
    print(error)
NameError: name 'error' is not defined
2025-08-25 13:57:18 ERROR root Failed to run callback function: Timert
Traceback (most recent call last):
  File "/main.py", line 13, in t
    print(error)
NameError: name 'error' is not defined
2025-08-25 13:57:19 ERROR root Failed to run callback function: Timert
Traceback (most recent call last):
  File "/main.py", line 13, in t
    print(error)
NameError: name 'error' is not defined
2025-08-25 13:57:20 ERROR root Failed to run callback function: Timert
Traceback (most recent call last):
  File "/main.py", line 13, in t
    print(error)
NameError: name 'error' is not defined
2025-08-25 13:57:21 ERROR root Failed to run callback function: Timert
Traceback (most recent call last):
  File "/main.py", line 13, in t
    print(error)
NameError: name 'error' is not defined
2025-08-25 13:57:22 ERROR root Failed to run callback function: Timert
Traceback (most recent call last):
  File "/main.py", line 13, in t
    print(error)
NameError: name 'error' is not defined
2025-08-25 13:57:23 ERROR root Failed to run callback function: Timert
Traceback (most recent call last):
  File "/main.py", line 13, in t
    print(error)
NameError: name 'error' is not defined
2025-08-25 13:57:24 ERROR root Failed to run callback function: Timert
Traceback (most recent call last):
  File "/main.py", line 13, in t
    print(error)
NameError: name 'error' is not defined
2025-08-25 13:57:25 ERROR root Failed to run callback function: Timert
Traceback (most recent call last):
  File "/main.py", line 13, in t
    print(error)
NameError: name 'error' is not defined
2025-08-25 13:57:26 ERROR root Failed to run callback function: Timert
Traceback (most recent call last):
  File "/main.py", line 13, in t
    print(error)
NameError: name 'error' is not defined
2025-08-25 13:57:27 ERROR root Failed to run callback function: Timert
Traceback (most recent call last):
  File "/main.py", line 13, in t
    print(error)
NameError: name 'error' is not defined
2025-08-25 13:57:28 ERROR root Failed to run callback function: Timert
Traceback (most recent call last):
  File "/main.py", line 13, in t
    print(error)
NameError: name 'error' is not defined
2025-08-25 13:57:29 ERROR root Failed to run callback function: Timert
Traceback (most recent call last):
  File "/main.py", line 13, in t
    print(error)
NameError: name 'error' is not defined
2025-08-25 13:57:30 ERROR root Failed to run callback function: Timert
Traceback (most recent call last):
  File "/main.py", line 13, in t
    print(error)
NameError: name 'error' is not defined
2025-08-25 13:57:31 ERROR root Failed to run callback function: Timert
Traceback (most recent call last):
  File "/main.py", line 13, in t
    print(error)
NameError: name 'error' is not defined
2025-08-25 13:57:32 ERROR root Failed to run callback function: Timert
Traceback (most recent call last):
  File "/main.py", line 13, in t
    print(error)
NameError: name 'error' is not defined
2025-08-25 13:57:33 ERROR root Failed to run callback function: Timert
Traceback (most recent call last):
  File "/main.py", line 13, in t
    print(error)
NameError: name 'error' is not defined
2025-08-25 13:57:34 ERROR root Failed to run callback function: Timert
Traceback (most recent call last):
  File "/main.py", line 13, in t
    print(error)
NameError: name 'error' is not defined
2025-08-25 13:57:35 ERROR root Failed to run callback function: Timert
Traceback (most recent call last):
  File "/main.py", line 13, in t
    print(error)
NameError: name 'error' is not defined
2025-08-25 13:57:36 ERROR root Failed to run callback function: Timert
Traceback (most recent call last):
  File "/main.py", line 13, in t
    print(error)
NameError: name 'error' is not defined
2025-08-25 13:57:37 ERROR root Failed to run callback function: Timert
Traceback (most recent call last):
  File "/main.py", line 13, in t
    print(error)
NameError: name 'error' is not defined
2025-08-25 13:57:38 ERROR root Failed to run callback function: Timert
Traceback (most recent call last):
  File "/main.py", line 13, in t
    print(error)
NameError: name 'error' is not defined
2025-08-25 13:57:39 ERROR root Failed to run callback function: Timert
Traceback (most recent call last):
  File "/main.py", line 13, in t
    print(error)
NameError: name 'error' is not defined
2025-08-25 13:57:40 ERROR root Failed to run callback function: Timert
Traceback (most recent call last):
  File "/main.py", line 13, in t
    print(error)
NameError: name 'error' is not defined
2025-08-25 13:57:41 ERROR root Failed to run callback function: Timert
Traceback (most recent call last):
  File "/main.py", line 13, in t
    print(error)
NameError: name 'error' is not defined
2025-08-25 13:57:42 ERROR root Failed to run callback function: Timert
Traceback (most recent call last):
  File "/main.py", line 13, in t
    print(error)
NameError: name 'error' is not defined
2025-08-25 13:57:43 ERROR root Failed to run callback function: Timert
Traceback (most recent call last):
  File "/main.py", line 13, in t
    print(error)
NameError: name 'error' is not defined
2025-08-25 13:57:44 ERROR root Failed to run callback function: Timert
Traceback (most recent call last):
  File "/main.py", line 13, in t
    print(error)
NameError: name 'error' is not defined
2025-08-25 13:57:45 ERROR root Failed to run callback function: Timert
Traceback (most recent call last):
  File "/main.py", line 13, in t
    print(error)
NameError: name 'error' is not defined
2025-08-25 13:57:46 ERROR root Failed to run callback function: Timert
Traceback (most recent call last):
  File "/main.py", line 13, in t
    print(error)
NameError: name 'error' is not defined
2025-08-25 13:57:47 ERROR root Failed to run callback function: Timert
Traceback (most recent call last):
  File "/main.py", line 13, in t
    print(error)
NameError: name 'error' is not defined
2025-08-25 13:57:48 ERROR root Failed to run callback function: Timert
Traceback (most recent call last):
  File "/main.py", line 13, in t
    print(error)
NameError: name 'error' is not defined
2025-08-25 13:57:49 ERROR root Failed to run callback function: Timert
Traceback (most recent call last):
  File "/main.py", line 13, in t
    print(error)
NameError: name 'error' is not defined
2025-08-25 13:57:50 ERROR root Failed to run callback function: Timert
Traceback (most recent call last):
  File "/main.py", line 13, in t
    print(error)
NameError: name 'error' is not defined
2025-08-25 13:57:51 ERROR root Failed to run callback function: Timert
Traceback (most recent call last):
  File "/main.py", line 13, in t
    print(error)
NameError: name 'error' is not defined
2025-08-25 13:57:52 ERROR root Failed to run callback function: Timert
Traceback (most recent call last):
  File "/main.py", line 13, in t
    print(error)
NameError: name 'error' is not defined
2025-08-25 13:57:53 ERROR root Failed to run callback function: Timert
Traceback (most recent call last):
  File "/main.py", line 13, in t
    print(error)
NameError: name 'error' is not defined
2025-08-25 13:57:54 ERROR root Failed to run callback function: Timert
Traceback (most recent call last):
  File "/main.py", line 13, in t
    print(error)
NameError: name 'error' is not defined
2025-08-25 13:57:55 ERROR root Failed to run callback function: Timert
Traceback (most recent call last):
  File "/main.py", line 13, in t
    print(error)
NameError: name 'error' is not defined
2025-08-25 13:57:56 ERROR root Failed to run callback function: Timert
Traceback (most recent call last):
  File "/main.py", line 13, in t
    print(error)
NameError: name 'error' is not defined
2025-08-25 13:57:57 ERROR root Failed to run callback function: Timert
Traceback (most recent call last):
  File "/main.py", line 13, in t
    print(error)
NameError: name 'error' is not defined
2025-08-25 13:57:58 ERROR root Failed to run callback function: Timert
Traceback (most recent call last):
  File "/main.py", line 13, in t
    print(error)
NameError: name 'error' is not defined
2025-08-25 13:57:59 ERROR root Failed to run callback function: Timert
Traceback (most recent call last):
  File "/main.py", line 13, in t
    print(error)
NameError: name 'error' is not defined
2025-08-25 13:58:00 ERROR root Failed to run callback function: Timert
Traceback (most recent call last):
  File "/main.py", line 13, in t
    print(error)
NameError: name 'error' is not defined
2025-08-25 13:58:01 ERROR root Failed to run callback function: Timert
Traceback (most recent call last):
  File "/main.py", line 13, in t
    print(error)
NameError: name 'error' is not defined
2025-08-25 13:58:02 ERROR root Failed to run callback function: Timert
Traceback (most recent call last):
  File "/main.py", line 13, in t
    print(error)
NameError: name 'error' is not defined
2025-08-25 13:58:03 ERROR root Failed to run callback function: Timert
Traceback (most recent call last):
  File "/main.py", line 13, in t
    print(error)
NameError: name 'error' is not defined
2025-08-25 13:58:04 ERROR root Failed to run callback function: Timert
Traceback (most recent call last):
  File "/main.py", line 13, in t
    print(error)
NameError: name 'error' is not defined
2025-08-25 13:58:05 ERROR root Failed to run callback function: Timert
Traceback (most recent call last):
  File "/main.py", line 13, in t
    print(error)
NameError: name 'error' is not defined
2025-08-25 13:58:06 ERROR root Failed to run callback function: Timert
Traceback (most recent call last):
  File "/main.py", line 13, in t
    print(error)
NameError: name 'error' is not defined
2025-08-25 13:58:07 ERROR root Failed to run callback function: Timert
Traceback (most recent call last):
  File "/main.py", line 13, in t
    print(error)
NameError: name 'error' is not defined
2025-08-25 13:58:08 ERROR root Failed to run callback function: Timert
Traceback (most recent call last):
  File "/main.py", line 13, in t
    print(error)
NameError: name 'error' is not defined
2025-08-25 13:58:09 ERROR root Failed to run callback function: Timert
Traceback (most recent call last):
  File "/main.py", line 13, in t
    print(error)
NameError: name 'error' is not defined
2025-08-25 13:58:10 ERROR root Failed to run callback function: Timert
Traceback (most recent call last):
  File "/main.py", line 13, in t
    print(error)
NameError: name 'error' is not defined
2025-08-25 13:58:11 ERROR root Failed to run callback function: Timert
Traceback (most recent call last):
  File "/main.py", line 13, in t
    print(error)
NameError: name 'error' is not defined
2025-08-25 13:58:12 ERROR root Failed to run callback function: Timert
Traceback (most recent call last):
  File "/main.py", line 13, in t
    print(error)
NameError: name 'error' is not defined
2025-08-25 13:58:13 ERROR root Failed to run callback function: Timert
Traceback (most recent call last):
  File "/main.py", line 13, in t
    print(error)
NameError: name 'error' is not defined
2025-08-25 13:58:14 ERROR root Failed to run callback function: Timert
Traceback (most recent call last):
  File "/main.py", line 13, in t
    print(error)
NameError: name 'error' is not defined
2025-08-25 13:58:15 ERROR root Failed to run callback function: Timert
Traceback (most recent call last):
  File "/main.py", line 13, in t
    print(error)
NameError: name 'error' is not defined
2025-08-25 13:58:16 ERROR root Failed to run callback function: Timert
Traceback (most recent call last):
  File "/main.py", line 13, in t
    print(error)
NameError: name 'error' is not defined
2025-08-25 13:58:17 ERROR root Failed to run callback function: Timert
Traceback (most recent call last):
  File "/main.py", line 13, in t
    print(error)
NameError: name 'error' is not defined
2025-08-25 13:58:19 ERROR root Failed to run callback function: Timert
Traceback (most recent call last):
  File "/main.py", line 13, in t
    print(error)
NameError: name 'error' is not defined
2025-08-25 13:58:20 ERROR root Failed to run callback function: Timert
Traceback (most recent call last):
  File "/main.py", line 13, in t
    print(error)
NameError: name 'error' is not defined
2025-08-25 13:58:21 ERROR root Failed to run callback function: Timert
Traceback (most recent call last):
  File "/main.py", line 13, in t
    print(error)
NameError: name 'error' is not defined
2025-08-25 13:58:22 ERROR root Failed to run callback function: Timert
Traceback (most recent call last):
  File "/main.py", line 13, in t
    print(error)
NameError: name 'error' is not defined
2025-08-25 13:58:23 ERROR root Failed to run callback function: Timert
Traceback (most recent call last):
  File "/main.py", line 13, in t
    print(error)
NameError: name 'error' is not defined
2025-08-25 13:58:24 ERROR root Failed to run callback function: Timert
Traceback (most recent call last):
  File "/main.py", line 13, in t
    print(error)
NameError: name 'error' is not defined
2025-08-25 13:58:25 ERROR root Failed to run callback function: Timert
Traceback (most recent call last):
  File "/main.py", line 13, in t
    print(error)
NameError: name 'error' is not defined
2025-08-25 13:58:26 ERROR root Failed to run callback function: Timert
Traceback (most recent call last):
  File "/main.py", line 13, in t
    print(error)
NameError: name 'error' is not defined
2025-08-25 13:58:27 ERROR root Failed to run callback function: Timert
Traceback (most recent call last):
  File "/main.py", line 13, in t
    print(error)
NameError: name 'error' is not defined
2025-08-25 13:58:28 ERROR root Failed to run callback function: Timert
Traceback (most recent call last):
  File "/main.py", line 13, in t
    print(error)
NameError: name 'error' is not defined
2025-08-25 13:58:29 ERROR root Failed to run callback function: Timert
Traceback (most recent call last):
  File "/main.py", line 13, in t
    print(error)
NameError: name 'error' is not defined
2025-08-25 13:58:30 ERROR root Failed to run callback function: Timert
Traceback (most recent call last):
  File "/main.py", line 13, in t
    print(error)
NameError: name 'error' is not defined
2025-08-25 13:58:31 ERROR root Failed to run callback function: Timert
Traceback (most recent call last):
  File "/main.py", line 13, in t
    print(error)
NameError: name 'error' is not defined
2025-08-25 13:58:32 ERROR root Failed to run callback function: Timert
Traceback (most recent call last):
  File "/main.py", line 13, in t
    print(error)
NameError: name 'error' is not defined
2025-08-25 13:58:33 ERROR root Failed to run callback function: Timert
Traceback (most recent call last):
  File "/main.py", line 13, in t
    print(error)
NameError: name 'error' is not defined
2025-08-25 13:58:34 ERROR root Failed to run callback function: Timert
Traceback (most recent call last):
  File "/main.py", line 13, in t
    print(error)
NameError: name 'error' is not defined
2025-08-25 13:58:35 ERROR root Failed to run callback function: Timert
Traceback (most recent call last):
  File "/main.py", line 13, in t
    print(error)
NameError: name 'error' is not defined
2025-08-25 13:58:36 ERROR root Failed to run callback function: Timert
Traceback (most recent call last):
  File "/main.py", line 13, in t
    print(error)
NameError: name 'error' is not defined
2025-08-25 13:58:37 ERROR root Failed to run callback function: Timert
Traceback (most recent call last):
  File "/main.py", line 13, in t
    print(error)
NameError: name 'error' is not defined
2025-08-25 13:58:38 ERROR root Failed to run callback function: Timert
Traceback (most recent call last):
  File "/main.py", line 13, in t
    print(error)
NameError: name 'error' is not defined
2025-08-25 13:58:39 ERROR root Failed to run callback function: Timert
Traceback (most recent call last):
  File "/main.py", line 13, in t
    print(error)
NameError: name 'error' is not defined
2025-08-25 13:58:40 ERROR root Failed to run callback function: Timert
Traceback (most recent call last):
  File "/main.py", line 13, in t
    print(error)
NameError: name 'error' is not defined
2025-08-25 13:58:41 ERROR root Failed to run callback function: Timert
Traceback (most recent call last):
  File "/main.py", line 13, in t
    print(error)
NameError: name 'error' is not defined
2025-08-25 13:58:42 ERROR root Failed to run callback function: Timert
Traceback (most recent call last):
  File "/main.py", line 13, in t
    print(error)
NameError: name 'error' is not defined
2025-08-25 13:58:43 ERROR root Failed to run callback function: Timert
Traceback (most recent call last):
  File "/main.py", line 13, in t
    print(error)
NameError: name 'error' is not defined
2025-08-25 13:58:44 ERROR root Failed to run callback function: Timert
Traceback (most recent call last):
  File "/main.py", line 13, in t
    print(error)
NameError: name 'error' is not defined
2025-08-25 13:58:45 ERROR root Failed to run callback function: Timert
Traceback (most recent call last):
  File "/main.py", line 13, in t
    print(error)
NameError: name 'error' is not defined
2025-08-25 13:58:46 ERROR root Failed to run callback function: Timert
Traceback (most recent call last):
  File "/main.py", line 13, in t
    print(error)
NameError: name 'error' is not defined
2025-08-25 13:58:47 ERROR root Failed to run callback function: Timert
Traceback (most recent call last):
  File "/main.py", line 13, in t
    print(error)
NameError: name 'error' is not defined
2025-08-25 13:58:48 ERROR root Failed to run callback function: Timert
Traceback (most recent call last):
  File "/main.py", line 13, in t
    print(error)
NameError: name 'error' is not defined
2025-08-25 13:58:49 ERROR root Failed to run callback function: Timert
Traceback (most recent call last):
  File "/main.py", line 13, in t
    print(error)
NameError: name 'error' is not defined
2025-08-25 13:58:50 ERROR root Failed to run callback function: Timert
Traceback (most recent call last):
  File "/main.py", line 13, in t
    print(error)
NameError: name 'error' is not defined
2025-08-25 13:58:51 ERROR root Failed to run callback function: Timert
Traceback (most recent call last):
  File "/main.py", line 13, in t
    print(error)
NameError: name 'error' is not defined
2025-08-25 13:58:52 ERROR root Failed to run callback function: Timert
Traceback (most recent call last):
  File "/main.py", line 13, in t
    print(error)
NameError: name 'error' is not defined
2025-08-25 13:58:53 ERROR root Failed to run callback function: Timert
Traceback (most recent call last):
  File "/main.py", line 13, in t
    print(error)
NameError: name 'error' is not defined
2025-08-25 13:58:54 ERROR root Failed to run callback function: Timert
Traceback (most recent call last):
  File "/main.py", line 13, in t
    print(error)
NameError: name 'error' is not defined
2025-08-25 13:58:55 ERROR root Failed to run callback function: Timert
Traceback (most recent call last):
  File "/main.py", line 13, in t
    print(error)
NameError: name 'error' is not defined
2025-08-25 13:58:56 ERROR root Failed to run callback function: Timert
Traceback (most recent call last):
  File "/main.py", line 13, in t
    print(error)
NameError: name 'error' is not defined
2025-08-25 13:58:57 ERROR root Failed to run callback function: Timert
Traceback (most recent call last):
  File "/main.py", line 13, in t
    print(error)
NameError: name 'error' is not defined
2025-08-25 13:58:58 ERROR root Failed to run callback function: Timert
Traceback (most recent call last):
  File "/main.py", line 13, in t
    print(error)
NameError: name 'error' is not defined
2025-08-25 13:58:59 ERROR root Failed to run callback function: Timert
Traceback (most recent call last):
  File "/main.py", line 13, in t
    print(error)
NameError: name 'error' is not defined
2025-08-25 13:59:00 ERROR root Failed to run callback function: Timert
Traceback (most recent call last):
  File "/main.py", line 13, in t
    print(error)
NameError: name 'error' is not defined
2025-08-25 13:59:01 ERROR root Failed to run callback function: Timert
Traceback (most recent call last):
  File "/main.py", line 13, in t
    print(error)
NameError: name 'error' is not defined
2025-08-25 13:59:02 ERROR root Failed to run callback function: Timert
Traceback (most recent call last):
  File "/main.py", line 13, in t
    print(error)
NameError: name 'error' is not defined
2025-08-25 13:59:03 ERROR root Failed to run callback function: Timert
Traceback (most recent call last):
  File "/main.py", line 13, in t
    print(error)
NameError: name 'error' is not defined
2025-08-25 13:59:04 ERROR root Failed to run callback function: Timert
Traceback (most recent call last):
  File "/main.py", line 13, in t
    print(error)
NameError: name 'error' is not defined
2025-08-25 13:59:05 ERROR root Failed to run callback function: Timert
Traceback (most recent call last):
  File "/main.py", line 13, in t
    print(error)
NameError: name 'error' is not defined
2025-08-25 13:59:06 ERROR root Failed to run callback function: Timert
Traceback (most recent call last):
  File "/main.py", line 13, in t
    print(error)
NameError: name 'error' is not defined
2025-08-25 13:59:07 ERROR root Failed to run callback function: Timert
Traceback (most recent call last):
  File "/main.py", line 13, in t
    print(error)
NameError: name 'error' is not defined
2025-08-25 13:59:08 ERROR root Failed to run callback function: Timert
Traceback (most recent call last):
  File "/main.py", line 13, in t
    print(error)
NameError: name 'error' is not defined
2025-08-25 13:59:09 ERROR root Failed to run callback function: Timert
Traceback (most recent call last):
  File "/main.py", line 13, in t
    print(error)
NameError: name 'error' is not defined
2025-08-25 13:59:10 ERROR root Failed to run callback function: Timert
Traceback (most recent call last):
  File "/main.py", line 13, in t
    print(error)
NameError: name 'error' is not defined
2025-08-25 13:59:11 ERROR root Failed to run callback function: Timert
Traceback (most recent call last):
  File "/main.py", line 13, in t
    print(error)
NameError: name 'error' is not defined
2025-08-25 13:59:12 ERROR root Failed to run callback function: Timert
Traceback (most recent call last):
  File "/main.py", line 13, in t
    print(error)
NameError: name 'error' is not defined
2025-08-25 13:59:13 ERROR root Failed to run callback function: Timert
Traceback (most recent call last):
  File "/main.py", line 13, in t
    print(error)
NameError: name 'error' is not defined
2025-08-25 13:59:14 ERROR root Failed to run callback function: Timert
Traceback (most recent call last):
  File "/main.py", line 13, in t
    print(error)
NameError: name 'error' is not defined
2025-08-25 13:59:15 ERROR root Failed to run callback function: Timert
Traceback (most recent call last):
  File "/main.py", line 13, in t
    print(error)
NameError: name 'error' is not defined
2025-08-25 13:59:16 ERROR root Failed to run callback function: Timert
Traceback (most recent call last):
  File "/main.py", line 13, in t
    print(error)
NameError: name 'error' is not defined
2025-08-25 13:59:17 ERROR root Failed to run callback function: Timert
Traceback (most recent call last):
  File "/main.py", line 13, in t
    print(error)
NameError: name 'error' is not defined
2025-08-25 13:59:18 ERROR root Failed to run callback function: Timert
Traceback (most recent call last):
  File "/main.py", line 13, in t
    print(error)
NameError: name 'error' is not defined
2025-08-25 13:59:19 ERROR root Failed to run callback function: Timert
Traceback (most recent call last):
  File "/main.py", line 13, in t
    print(error)
NameError: name 'error' is not defined
2025-08-25 13:59:20 ERROR root Failed to run callback function: Timert
Traceback (most recent call last):
  File "/main.py", line 13, in t
    print(error)
NameError: name 'error' is not defined
2025-08-25 13:59:21 ERROR root Failed to run callback function: Timert
Traceback (most recent call last):
  File "/main.py", line 13, in t
    print(error)
NameError: name 'error' is not defined
2025-08-25 13:59:22 ERROR root Failed to run callback function: Timert
Traceback (most recent call last):
  File "/main.py", line 13, in t
    print(error)
NameError: name 'error' is not defined
2025-08-25 13:59:23 ERROR root Failed to run callback function: Timert
Traceback (most recent call last):
  File "/main.py", line 13, in t
    print(error)
NameError: name 'error' is not defined
2025-08-25 13:59:24 ERROR root Failed to run callback function: Timert
Traceback (most recent call last):
  File "/main.py", line 13, in t
    print(error)
NameError: name 'error' is not defined
2025-08-25 13:59:25 ERROR root Failed to run callback function: Timert
Traceback (most recent call last):
  File "/main.py", line 13, in t
    print(error)
NameError: name 'error' is not defined
2025-08-25 13:59:26 ERROR root Failed to run callback function: Timert
Traceback (most recent call last):
  File "/main.py", line 13, in t
    print(error)
NameError: name 'error' is not defined
2025-08-25 13:59:27 ERROR root Failed to run callback function: Timert
Traceback (most recent call last):
  File "/main.py", line 13, in t
    print(error)
NameError: name 'error' is not defined
2025-08-25 13:59:28 ERROR root Failed to run callback function: Timert
Traceback (most recent call last):
  File "/main.py", line 13, in t
    print(error)
NameError: name 'error' is not defined
2025-08-25 13:59:29 ERROR root Failed to run callback function: Timert
Traceback (most recent call last):
  File "/main.py", line 13, in t
    print(error)
NameError: name 'error' is not defined
2025-08-25 13:59:30 ERROR root Failed to run callback function: Timert
Traceback (most recent call last):
  File "/main.py", line 13, in t
    print(error)
NameError: name 'error' is not defined
2025-08-25 13:59:31 ERROR root Failed to run callback function: Timert
Traceback (most recent call last):
  File "/main.py", line 13, in t
    print(error)
NameError: name 'error' is not defined
2025-08-25 13:59:32 ERROR root Failed to run callback function: Timert
Traceback (most recent call last):
  File "/main.py", line 13, in t
    print(error)
NameError: name 'error' is not defined
2025-08-25 13:59:33 ERROR root Failed to run callback function: Timert
Traceback (most recent call last):
  File "/main.py", line 13, in t
    print(error)
NameError: name 'error' is not defined
2025-08-25 13:59:34 ERROR root Failed to run callback function: Timert
Traceback (most recent call last):
  File "/main.py", line 13, in t
    print(error)
NameError: name 'error' is not defined
2025-08-25 13:59:35 ERROR root Failed to run callback function: Timert
Traceback (most recent call last):
  File "/main.py", line 13, in t
    print(error)
NameError: name 'error' is not defined
2025-08-25 13:59:36 ERROR root Failed to run callback function: Timert
Traceback (most recent call last):
  File "/main.py", line 13, in t
    print(error)
NameError: name 'error' is not defined
2025-08-25 13:59:37 ERROR root Failed to run callback function: Timert
Traceback (most recent call last):
  File "/main.py", line 13, in t
    print(error)
NameError: name 'error' is not defined
2025-08-25 13:59:38 ERROR root Failed to run callback function: Timert
Traceback (most recent call last):
  File "/main.py", line 13, in t
    print(error)
NameError: name 'error' is not defined
2025-08-25 13:59:39 ERROR root Failed to run callback function: Timert
Traceback (most recent call last):
  File "/main.py", line 13, in t
    print(error)
NameError: name 'error' is not defined
2025-08-25 13:59:40 ERROR root Failed to run callback function: Timert
Traceback (most recent call last):
  File "/main.py", line 13, in t
    print(error)
NameError: name 'error' is not defined
2025-08-25 13:59:41 ERROR root Failed to run callback function: Timert
Traceback (most recent call last):
  File "/main.py", line 13, in t
    print(error)
NameError: name 'error' is not defined
2025-08-25 13:59:42 ERROR root Failed to run callback function: Timert
Traceback (most recent call last):
  File "/main.py", line 13, in t
    print(error)
NameError: name 'error' is not defined
2025-08-25 13:59:43 ERROR root Failed to run callback function: Timert
Traceback (most recent call last):
  File "/main.py", line 13, in t
    print(error)
NameError: name 'error' is not defined
2025-08-25 13:59:44 ERROR root Failed to run callback function: Timert
Traceback (most recent call last):
  File "/main.py", line 13, in t
    print(error)
NameError: name 'error' is not defined
2025-08-25 13:59:45 ERROR root Failed to run callback function: Timert
Traceback (most recent call last):
  File "/main.py", line 13, in t
    print(error)
NameError: name 'error' is not defined
2025-08-25 13:59:46 ERROR root Failed to run callback function: Timert
Traceback (most recent call last):
  File "/main.py", line 13, in t
    print(error)
NameError: name 'error' is not defined
2025-08-25 13:59:47 ERROR root Failed to run callback function: Timert
Traceback (most recent call last):
  File "/main.py", line 13, in t
    print(error)
NameError: name 'error' is not defined
2025-08-25 13:59:49 ERROR root Failed to run callback function: Timert
Traceback (most recent call last):
  File "/main.py", line 13, in t
    print(error)
NameError: name 'error' is not defined
2025-08-25 13:59:50 ERROR root Failed to run callback function: Timert
Traceback (most recent call last):
  File "/main.py", line 13, in t
    print(error)
NameError: name 'error' is not defined
2025-08-25 13:59:51 ERROR root Failed to run callback function: Timert
Traceback (most recent call last):
  File "/main.py", line 13, in t
    print(error)
NameError: name 'error' is not defined
2025-08-25 13:59:52 ERROR root Failed to run callback function: Timert
Traceback (most recent call last):
  File "/main.py", line 13, in t
    print(error)
NameError: name 'error' is not defined
2025-08-25 13:59:53 ERROR root Failed to run callback function: Timert
Traceback (most recent call last):
  File "/main.py", line 13, in t
    print(error)
NameError: name 'error' is not defined
2025-08-25 13:59:54 ERROR root Failed to run callback function: Timert
Traceback (most recent call last):
  File "/main.py", line 13, in t
    print(error)
NameError: name 'error' is not defined
2025-08-25 13:59:55 ERROR root Failed to run callback function: Timert
Traceback (most recent call last):
  File "/main.py", line 13, in t
    print(error)
NameError: name 'error' is not defined
2025-08-25 13:59:56 ERROR root Failed to run callback function: Timert
Traceback (most recent call last):
  File "/main.py", line 13, in t
    print(error)
NameError: name 'error' is not defined
2025-08-25 13:59:57 ERROR root Failed to run callback function: Timert
Traceback (most recent call last):
  File "/main.py", line 13, in t
    print(error)
NameError: name 'error' is not defined
2025-08-25 13:59:58 ERROR root Failed to run callback function: Timert
Traceback (most recent call last):
  File "/main.py", line 13, in t
    print(error)
NameError: name 'error' is not defined
2025-08-25 13:59:59 ERROR root Failed to run callback function: Timert
Traceback (most recent call last):
  File "/main.py", line 13, in t
    print(error)
NameError: name 'error' is not defined
2025-08-25 14:00:00 ERROR root Failed to run callback function: Timert
Traceback (most recent call last):
  File "/main.py", line 13, in t
    print(error)
NameError: name 'error' is not defined
2025-08-25 14:00:01 ERROR root Failed to run callback function: Timert
Traceback (most recent call last):
  File "/main.py", line 13, in t
    print(error)
NameError: name 'error' is not defined
2025-08-25 14:00:02 ERROR root Failed to run callback function: Timert
Traceback (most recent call last):
  File "/main.py", line 13, in t
    print(error)
NameError: name 'error' is not defined
2025-08-25 14:00:03 ERROR root Failed to run callback function: Timert
Traceback (most recent call last):
  File "/main.py", line 13, in t
    print(error)
NameError: name 'error' is not defined
2025-08-25 14:00:04 ERROR root Failed to run callback function: Timert
Traceback (most recent call last):
  File "/main.py", line 13, in t
    print(error)
NameError: name 'error' is not defined
2025-08-25 14:00:05 ERROR root Failed to run callback function: Timert
Traceback (most recent call last):
  File "/main.py", line 13, in t
    print(error)
NameError: name 'error' is not defined
2025-08-25 14:00:06 ERROR root Failed to run callback function: Timert
Traceback (most recent call last):
  File "/main.py", line 13, in t
    print(error)
NameError: name 'error' is not defined
2025-08-25 14:00:07 ERROR root Failed to run callback function: Timert
Traceback (most recent call last):
  File "/main.py", line 13, in t
    print(error)
NameError: name 'error' is not defined
2025-08-25 14:00:08 ERROR root Failed to run callback function: Timert
Traceback (most recent call last):
  File "/main.py", line 13, in t
    print(error)
NameError: name 'error' is not defined
2025-08-25 14:00:09 ERROR root Failed to run callback function: Timert
Traceback (most recent call last):
  File "/main.py", line 13, in t
    print(error)
NameError: name 'error' is not defined
2025-08-25 14:00:10 ERROR root Failed to run callback function: Timert
Traceback (most recent call last):
  File "/main.py", line 13, in t
    print(error)
NameError: name 'error' is not defined
2025-08-25 14:00:11 ERROR root Failed to run callback function: Timert
Traceback (most recent call last):
  File "/main.py", line 13, in t
    print(error)
NameError: name 'error' is not defined
2025-08-25 14:00:12 ERROR root Failed to run callback function: Timert
Traceback (most recent call last):
  File "/main.py", line 13, in t
    print(error)
NameError: name 'error' is not defined
2025-08-25 14:00:13 ERROR root Failed to run callback function: Timert
Traceback (most recent call last):
  File "/main.py", line 13, in t
    print(error)
NameError: name 'error' is not defined
2025-08-25 14:00:14 ERROR root Failed to run callback function: Timert
Traceback (most recent call last):
  File "/main.py", line 13, in t
    print(error)
NameError: name 'error' is not defined
2025-08-25 14:00:15 ERROR root Failed to run callback function: Timert
Traceback (most recent call last):
  File "/main.py", line 13, in t
    print(error)
NameError: name 'error' is not defined
2025-08-25 14:00:16 ERROR root Failed to run callback function: Timert
Traceback (most recent call last):
  File "/main.py", line 13, in t
    print(error)
NameError: name 'error' is not defined
2025-08-25 14:00:17 ERROR root Failed to run callback function: Timert
Traceback (most recent call last):
  File "/main.py", line 13, in t
    print(error)
NameError: name 'error' is not defined
2025-08-25 14:00:18 ERROR root Failed to run callback function: Timert
Traceback (most recent call last):
  File "/main.py", line 13, in t
    print(error)
NameError: name 'error' is not defined
2025-08-25 14:00:19 ERROR root Failed to run callback function: Timert
Traceback (most recent call last):
  File "/main.py", line 13, in t
    print(error)
NameError: name 'error' is not defined
2025-08-25 14:00:20 ERROR root Failed to run callback function: Timert
Traceback (most recent call last):
  File "/main.py", line 13, in t
    print(error)
NameError: name 'error' is not defined
2025-08-25 14:00:21 ERROR root Failed to run callback function: Timert
Traceback (most recent call last):
  File "/main.py", line 13, in t
    print(error)
NameError: name 'error' is not defined
2025-08-25 14:00:22 ERROR root Failed to run callback function: Timert
Traceback (most recent call last):
  File "/main.py", line 13, in t
    print(error)
NameError: name 'error' is not defined
2025-08-25 14:00:23 ERROR root Failed to run callback function: Timert
Traceback (most recent call last):
  File "/main.py", line 13, in t
    print(error)
NameError: name 'error' is not defined
2025-08-25 14:00:24 ERROR root Failed to run callback function: Timert
Traceback (most recent call last):
  File "/main.py", line 13, in t
    print(error)
NameError: name 'error' is not defined
2025-08-25 14:00:25 ERROR root Failed to run callback function: Timert
Traceback (most recent call last):
  File "/main.py", line 13, in t
    print(error)
NameError: name 'error' is not defined
2025-08-25 14:00:26 ERROR root Failed to run callback function: Timert
Traceback (most recent call last):
  File "/main.py", line 13, in t
    print(error)
NameError: name 'error' is not defined
2025-08-25 14:00:27 ERROR root Failed to run callback function: Timert
Traceback (most recent call last):
  File "/main.py", line 13, in t
    print(error)
NameError: name 'error' is not defined
2025-08-25 14:00:28 ERROR root Failed to run callback function: Timert
Traceback (most recent call last):
  File "/main.py", line 13, in t
    print(error)
NameError: name 'error' is not defined
2025-08-25 14:00:29 ERROR root Failed to run callback function: Timert
Traceback (most recent call last):
  File "/main.py", line 13, in t
    print(error)
NameError: name 'error' is not defined
2025-08-25 14:00:30 ERROR root Failed to run callback function: Timert
Traceback (most recent call last):
  File "/main.py", line 13, in t
    print(error)
NameError: name 'error' is not defined
2025-08-25 14:00:31 ERROR root Failed to run callback function: Timert
Traceback (most recent call last):
  File "/main.py", line 13, in t
    print(error)
NameError: name 'error' is not defined
2025-08-25 14:00:32 ERROR root Failed to run callback function: Timert
Traceback (most recent call last):
  File "/main.py", line 13, in t
    print(error)
NameError: name 'error' is not defined
2025-08-25 14:00:33 ERROR root Failed to run callback function: Timert
Traceback (most recent call last):
  File "/main.py", line 13, in t
    print(error)
NameError: name 'error' is not defined
2025-08-25 14:00:34 ERROR root Failed to run callback function: Timert
Traceback (most recent call last):
  File "/main.py", line 13, in t
    print(error)
NameError: name 'error' is not defined
2025-08-25 14:00:35 ERROR root Failed to run callback function: Timert
Traceback (most recent call last):
  File "/main.py", line 13, in t
    print(error)
NameError: name 'error' is not defined
2025-08-25 14:00:36 ERROR root Failed to run callback function: Timert
Traceback (most recent call last):
  File "/main.py", line 13, in t
    print(error)
NameError: name 'error' is not defined
2025-08-25 14:00:37 ERROR root Failed to run callback function: Timert
Traceback (most recent call last):
  File "/main.py", line 13, in t
    print(error)
NameError: name 'error' is not defined
2025-08-25 14:00:38 ERROR root Failed to run callback function: Timert
Traceback (most recent call last):
  File "/main.py", line 13, in t
    print(error)
NameError: name 'error' is not defined
2025-08-25 14:00:39 ERROR root Failed to run callback function: Timert
Traceback (most recent call last):
  File "/main.py", line 13, in t
    print(error)
NameError: name 'error' is not defined
2025-08-25 14:00:40 ERROR root Failed to run callback function: Timert
Traceback (most recent call last):
  File "/main.py", line 13, in t
    print(error)
NameError: name 'error' is not defined
2025-08-25 14:00:41 ERROR root Failed to run callback function: Timert
Traceback (most recent call last):
  File "/main.py", line 13, in t
    print(error)
NameError: name 'error' is not defined
2025-08-25 14:00:42 ERROR root Failed to run callback function: Timert
Traceback (most recent call last):
  File "/main.py", line 13, in t
    print(error)
NameError: name 'error' is not defined
2025-08-25 14:00:43 ERROR root Failed to run callback function: Timert
Traceback (most recent call last):
  File "/main.py", line 13, in t
    print(error)
NameError: name 'error' is not defined
2025-08-25 14:00:44 ERROR root Failed to run callback function: Timert
Traceback (most recent call last):
  File "/main.py", line 13, in t
    print(error)
NameError: name 'error' is not defined
2025-08-25 14:00:45 ERROR root Failed to run callback function: Timert
Traceback (most recent call last):
  File "/main.py", line 13, in t
    print(error)
NameError: name 'error' is not defined
2025-08-25 14:00:46 ERROR root Failed to run callback function: Timert
Traceback (most recent call last):
  File "/main.py", line 13, in t
    print(error)
NameError: name 'error' is not defined
2025-08-25 14:00:47 ERROR root Failed to run callback function: Timert
Traceback (most recent call last):
  File "/main.py", line 13, in t
    print(error)
NameError: name 'error' is not defined
2025-08-25 14:00:48 ERROR root Failed to run callback function: Timert
Traceback (most recent call last):
  File "/main.py", line 13, in t
    print(error)
NameError: name 'error' is not defined
2025-08-25 14:00:49 ERROR root Failed to run callback function: Timert
Traceback (most recent call last):
  File "/main.py", line 13, in t
    print(error)
NameError: name 'error' is not defined
2025-08-25 14:00:50 ERROR root Failed to run callback function: Timert
Traceback (most recent call last):
  File "/main.py", line 13, in t
    print(error)
NameError: name 'error' is not defined
2025-08-25 14:00:51 ERROR root Failed to run callback function: Timert
Traceback (most recent call last):
  File "/main.py", line 13, in t
    print(error)
NameError: name 'error' is not defined
2025-08-25 14:00:52 ERROR root Failed to run callback function: Timert
Traceback (most recent call last):
  File "/main.py", line 13, in t
    print(error)
NameError: name 'error' is not defined
2025-08-25 14:00:53 ERROR root Failed to run callback function: Timert
Traceback (most recent call last):
  File "/main.py", line 13, in t
    print(error)
NameError: name 'error' is not defined
2025-08-25 14:00:54 ERROR root Failed to run callback function: Timert
Traceback (most recent call last):
  File "/main.py", line 13, in t
    print(error)
NameError: name 'error' is not defined
2025-08-25 14:00:55 ERROR root Failed to run callback function: Timert
Traceback (most recent call last):
  File "/main.py", line 13, in t
    print(error)
NameError: name 'error' is not defined
2025-08-25 14:00:56 ERROR root Failed to run callback function: Timert
Traceback (most recent call last):
  File "/main.py", line 13, in t
    print(error)
NameError: name 'error' is not defined
2025-08-25 14:00:57 ERROR root Failed to run callback function: Timert
Traceback (most recent call last):
  File "/main.py", line 13, in t
    print(error)
NameError: name 'error' is not defined
2025-08-25 14:00:58 ERROR root Failed to run callback function: Timert
Traceback (most recent call last):
  File "/main.py", line 13, in t
    print(error)
NameError: name 'error' is not defined
2025-08-25 14:00:59 ERROR root Failed to run callback function: Timert
Traceback (most recent call last):
  File "/main.py", line 13, in t
    print(error)
NameError: name 'error' is not defined
2025-08-25 14:01:00 ERROR root Failed to run callback function: Timert
Traceback (most recent call last):
  File "/main.py", line 13, in t
    print(error)
NameError: name 'error' is not defined
2025-08-25 14:01:01 ERROR root Failed to run callback function: Timert
Traceback (most recent call last):
  File "/main.py", line 13, in t
    print(error)
NameError: name 'error' is not defined
2025-08-25 14:01:02 ERROR root Failed to run callback function: Timert
Traceback (most recent call last):
  File "/main.py", line 13, in t
    print(error)
NameError: name 'error' is not defined
2025-08-25 14:01:03 ERROR root Failed to run callback function: Timert
Traceback (most recent call last):
  File "/main.py", line 13, in t
    print(error)
NameError: name 'error' is not defined
2025-08-25 14:01:04 ERROR root Failed to run callback function: Timert
Traceback (most recent call last):
  File "/main.py", line 13, in t
    print(error)
NameError: name 'error' is not defined
2025-08-25 14:01:05 ERROR root Failed to run callback function: Timert
Traceback (most recent call last):
  File "/main.py", line 13, in t
    print(error)
NameError: name 'error' is not defined
2025-08-25 14:01:06 ERROR root Failed to run callback function: Timert
Traceback (most recent call last):
  File "/main.py", line 13, in t
    print(error)
NameError: name 'error' is not defined
2025-08-25 14:01:07 ERROR root Failed to run callback function: Timert
Traceback (most recent call last):
  File "/main.py", line 13, in t
    print(error)
NameError: name 'error' is not defined
2025-08-25 14:01:08 ERROR root Failed to run callback function: Timert
Traceback (most recent call last):
  File "/main.py", line 13, in t
    print(error)
NameError: name 'error' is not defined
2025-08-25 14:01:09 ERROR root Failed to run callback function: Timert
Traceback (most recent call last):
  File "/main.py", line 13, in t
    print(error)
NameError: name 'error' is not defined
